Workbook

Sheet Trade-off Board
A1: Brightline Logistics Model Deployment Trade-Off Board
A2: Measured on one Google Colab Tesla T4 using a controlled synthetic bill-of-lading classification workload
A3: Quality = mean of 3 seeds on 3,000 test documents. Latency and memory = seed-0 model, batch size 1, sequence length 128, 100 timed trials. pp = percentage points. Prepared for Sandra Whitfield, VP Engineering.
A4: Configuration | B4: Precision / Compression | C4: Total Parameters | D4: Parameter Reduction vs Baseline | E4: Weight Storage MB | F4: Storage Reduction vs Baseline | G4: Overall Accuracy Mean | H4: Accuracy Std Dev | I4: Accuracy Change vs Baseline | J4: Rare-Class Macro Recall | K4: Rare-Class Std Dev | L4: Rare-Class Change vs Baseline | M4: p50 Latency ms | N4: p95 Latency ms | O4: p95 Change vs Baseline | P4: Peak GPU Memory MB | Q4: Peak Memory Change vs Baseline | R4: Main Advantage | S4: Main Trade-off | T4: Residual Risk | U4: Final Rank
A5: FP32 Baseline Transformer | B5: FP32 (reference model) | C5: ='Benchmark Detail'!L5 -> 1259654 | D5: =1-C5/C5 -> 0 | E5: ='Benchmark Detail'!K5 -> 4.8051987 | F5: =1-E5/E5 -> 0 | G5: ='Quality by Seed'!C20 -> 0.97633333 | H5: ='Quality by Seed'!C21 -> 0.17638342 | I5: =(G5-G5)*100 -> 0 | J5: ='Quality by Seed'!F20 -> 0.96527778 | K5: ='Quality by Seed'!F21 -> 1.8788541 | L5: =(J5-J5)*100 -> 0 | M5: ='Benchmark Detail'!C5 -> 5.227631 | N5: ='Benchmark Detail'!D5 -> 6.5318771 | O5: =N5/N5-1 -> 0 | P5: ='Benchmark Detail'!I5 -> 75.402832 | Q5: =P5/P5-1 -> 0 | R5: Simplest, best-understood reference: no compression, custom attention or distillation. 97.63% overall accuracy at 5.23 ms p50. | S5: Largest weights (4.81 MB) and about twice the student's p95 latency (6.53 ms vs 3.37 ms). | T5: Rare-class recall varies 1.88 pp (std dev) across seeds; synthetic data only; one GPU type. | U5: 2
A6: FP32 Linear Attention | B6: FP32; linear (ELU+1) attention in place of softmax attention; same parameter count | C6: ='Benchmark Detail'!L6 -> 1259654 | D6: =1-C6/C5 -> 0 | E6: ='Benchmark Detail'!K6 -> 4.8051987 | F6: =1-E6/E5 -> 0 | G6: ='Quality by Seed'!C22 -> 0.98188889 | H6: ='Quality by Seed'!C23 -> 0.10183502 | I6: =(G6-G5)*100 -> 0.55555556 | J6: ='Quality by Seed'!F22 -> 0.96666667 | K6: ='Quality by Seed'!F23 -> 0.72168784 | L6: =(J6-J5)*100 -> 0.13888889 | M6: ='Benchmark Detail'!C6 -> 6.9316315 | N6: ='Benchmark Detail'!D6 -> 8.2889259 | O6: =N6/N5-1 -> 0.26899599 | P6: ='Benchmark Detail'!I6 -> 75.402832 | Q6: =P6/P5-1 -> 0 | R6: Highest mean overall accuracy (98.19%, +0.56 pp), above every baseline seed; rare-class recall similar to the baseline. | S6: Slower than the baseline at sequence length 128 (p95 +26.9%); no storage or peak-memory reduction. | T6: Accuracy edge is small (+0.56 pp); behavior at longer sequences was not tested; custom attention code to maintain. | U6: 3
A7: Mixed-Precision INT8 Baseline | B7: bitsandbytes INT8 on 16 hidden Linear layers; the 128 -> 6 classification head, embeddings and LayerNorm stay FP32 | C7: ='Benchmark Detail'!L7 -> 1259654 | D7: =1-C7/C5 -> 0 | E7: ='Benchmark Detail'!K7 -> 3.3120346 | F7: =1-E7/E5 -> 0.3107393 | G7: ='Quality by Seed'!C24 -> 0.97644444 | H7: ='Quality by Seed'!C25 -> 0.19245009 | I7: =(G7-G5)*100 -> 0.011111111 | J7: ='Quality by Seed'!F24 -> 0.96666667 | K7: ='Quality by Seed'!F25 -> 1.9094065 | L7: =(J7-J5)*100 -> 0.13888889 | M7: ='Benchmark Detail'!C7 -> 11.474539 | N7: ='Benchmark Detail'!D7 -> 13.280214 | O7: =N7/N5-1 -> 1.033139 | P7: ='Benchmark Detail'!I7 -> 73.912598 | Q7: =P7/P5-1 -> -0.019763639 | R7: Weight storage 31.1% smaller (3.31 MB) with overall accuracy unchanged (97.64%). | S7: Slowest model on the T4: p95 +103.3% vs baseline; peak GPU memory only -2.0%; the 6-class head could not be quantized. | T7: bitsandbytes INT8 targets CUDA GPUs and failed on the 128 -> 6 head, so a tablet runtime would need a different path; no speed benefit was shown even on the T4. | U7: 4
A8: Distilled Student | B8: FP32; distilled student (d=64, 2 layers, 2 heads) taught by the FP32 baseline | C8: ='Benchmark Detail'!L8 -> 431814 | D8: =1-C8/C5 -> 0.65719634 | E8: ='Benchmark Detail'!K8 -> 1.6472397 | F8: =1-E8/E5 -> 0.65719634 | G8: ='Quality by Seed'!C26 -> 0.97977778 | H8: ='Quality by Seed'!C27 -> 0.28349668 | I8: =(G8-G5)*100 -> 0.34444444 | J8: ='Quality by Seed'!F26 -> 0.95555556 | K8: ='Quality by Seed'!F27 -> 1.4632852 | L8: =(J8-J5)*100 -> -0.97222222 | M8: ='Benchmark Detail'!C8 -> 2.845486 | N8: ='Benchmark Detail'!D8 -> 3.3737753 | O8: =N8/N5-1 -> -0.48349069 | P8: ='Benchmark Detail'!I8 -> 69.53125 | Q8: =P8/P5-1 -> -0.077869516 | R8: Smallest and fastest: weights 65.7% smaller, p95 latency 48.3% lower, peak GPU memory 7.8% lower, with overall accuracy not lower than the baseline (97.98%). | S8: Mean rare-class macro recall 0.97 pp lower than baseline (95.56% vs 96.53%); needs a trained teacher and a distillation step. | T8: Possible rare-class trade-off: the decline is smaller than the baseline's seed spread, so it is not confirmed, but all three paired seeds were lower (7 more missed rare documents out of 720 across seeds). | U8: 1
A10: How to read this board
A11: Green fill marks the best value in a column (highest accuracy and recall; lowest storage, latency and memory). It is a guide, not a ranking; see the Recommendation sheet.
A12: Differences smaller than the observed seed-to-seed spread should be read as similar. Within seed spread: FP32 Linear Attention (Hazmat Recall, Oversize / Heavy-Haul Recall, Rare-Class Macro Recall); Mixed-Precision INT8 Baseline (Overall Accuracy, Hazmat Recall, Oversize / Heavy-Haul Recall, Rare-Class Macro Recall); Distilled Student (Hazmat Recall, Oversize / Heavy-Haul Recall, Rare-Class Macro Recall). Larger than the seed spread (only 3 seeds, no significance test run): FP32 Linear Attention (Overall Accuracy 3.15x); Distilled Student (Overall Accuracy 1.21x). Details: Quality by Seed sheet.
A13: Rare classes (Hazmat, Oversize / Heavy Haul) have only 120 test documents each, so one document is 0.83 pp. The Distilled Student's rare-class macro recall is 0.97 pp lower than the baseline; see Per-Class Results for each class.
A14: Peak GPU Memory is PyTorch allocator memory and includes a constant 65.06 MB that was already allocated before any model was loaded, so differences between rows are smaller in percentage terms than the model sizes alone suggest. Details: Benchmark Detail sheet.
A15: Measured on a Tesla T4 GPU as a controlled proxy. Android tablet hardware and runtimes were not tested, and the data is synthetic.
A17: Recommended to ship: Distilled Student (Rank 1), subject to checking rare-class recall on real Brightline documents. Full reasoning: Recommendation sheet.

Sheet Quality by Seed
A1: Quality by Seed: three seeds per configuration
A2: Test set: 3,000 documents (120 Hazmat, 120 Oversize / Heavy Haul). Each seed value is correct documents / test support; click a cell to see the counts.
A4: Configuration | B4: Seed | C4: Overall Accuracy | D4: Hazmat Recall | E4: Oversize / Heavy-Haul Recall | F4: Rare-Class Macro Recall | G4: Source (executed notebook output)
A5: FP32 Baseline Transformer | B5: 0 | C5: =2925/3000 -> 0.975 | D5: =112/120 -> 0.93333333 | E5: =115/120 -> 0.95833333 | F5: =(D5+E5)/2 -> 0.94583333 | G5: bol_experiment_cuda_run_v4_benchmark.ipynb, cell 14 output (per-seed table), seed 0
A6: FP32 Baseline Transformer | B6: 1 | C6: =2935/3000 -> 0.97833333 | D6: =113/120 -> 0.94166667 | E6: =119/120 -> 0.99166667 | F6: =(D6+E6)/2 -> 0.96666667 | G6: bol_experiment_cuda_run_v4_benchmark.ipynb, cell 14 output (per-seed table), seed 1
A7: FP32 Baseline Transformer | B7: 2 | C7: =2927/3000 -> 0.97566667 | D7: =117/120 -> 0.975 | E7: =119/120 -> 0.99166667 | F7: =(D7+E7)/2 -> 0.98333333 | G7: bol_experiment_cuda_run_v4_benchmark.ipynb, cell 14 output (per-seed table), seed 2
A8: FP32 Linear Attention | B8: 0 | C8: =2945/3000 -> 0.98166667 | D8: =114/120 -> 0.95 | E8: =117/120 -> 0.975 | F8: =(D8+E8)/2 -> 0.9625 | G8: bol_experiment_cuda_run_v4_benchmark.ipynb, cell 23 output (per-seed table), seed 0
A9: FP32 Linear Attention | B9: 1 | C9: =2949/3000 -> 0.983 | D9: =113/120 -> 0.94166667 | E9: =118/120 -> 0.98333333 | F9: =(D9+E9)/2 -> 0.9625 | G9: bol_experiment_cuda_run_v4_benchmark.ipynb, cell 23 output (per-seed table), seed 1
A10: FP32 Linear Attention | B10: 2 | C10: =2943/3000 -> 0.981 | D10: =115/120 -> 0.95833333 | E10: =119/120 -> 0.99166667 | F10: =(D10+E10)/2 -> 0.975 | G10: bol_experiment_cuda_run_v4_benchmark.ipynb, cell 23 output (per-seed table), seed 2
A11: Mixed-Precision INT8 Baseline | B11: 0 | C11: =2926/3000 -> 0.97533333 | D11: =112/120 -> 0.93333333 | E11: =115/120 -> 0.95833333 | F11: =(D11+E11)/2 -> 0.94583333 | G11: bol_experiment_cuda_run_v4_benchmark.ipynb, cell 31 output (per-seed table), seed 0
A12: Mixed-Precision INT8 Baseline | B12: 1 | C12: =2936/3000 -> 0.97866667 | D12: =114/120 -> 0.95 | E12: =119/120 -> 0.99166667 | F12: =(D12+E12)/2 -> 0.97083333 | G12: bol_experiment_cuda_run_v4_benchmark.ipynb, cell 31 output (per-seed table), seed 1
A13: Mixed-Precision INT8 Baseline | B13: 2 | C13: =2926/3000 -> 0.97533333 | D13: =117/120 -> 0.975 | E13: =119/120 -> 0.99166667 | F13: =(D13+E13)/2 -> 0.98333333 | G13: bol_experiment_cuda_run_v4_benchmark.ipynb, cell 31 output (per-seed table), seed 2
A14: Distilled Student | B14: 0 | C14: =2936/3000 -> 0.97866667 | D14: =109/120 -> 0.90833333 | E14: =117/120 -> 0.975 | F14: =(D14+E14)/2 -> 0.94166667 | G14: bol_experiment_cuda_run_v4_benchmark.ipynb, cell 38 output (per-seed table), seed 0
A15: Distilled Student | B15: 1 | C15: =2949/3000 -> 0.983 | D15: =113/120 -> 0.94166667 | E15: =116/120 -> 0.96666667 | F15: =(D15+E15)/2 -> 0.95416667 | G15: bol_experiment_cuda_run_v4_benchmark.ipynb, cell 38 output (per-seed table), seed 1
A16: Distilled Student | B16: 2 | C16: =2933/3000 -> 0.97766667 | D16: =116/120 -> 0.96666667 | E16: =117/120 -> 0.975 | F16: =(D16+E16)/2 -> 0.97083333 | G16: bol_experiment_cuda_run_v4_benchmark.ipynb, cell 38 output (per-seed table), seed 2
A18: Summary over the three seeds: mean and sample standard deviation (n - 1)
A19: Configuration | B19: Statistic (std dev in percentage points) | C19: Overall Accuracy | D19: Hazmat Recall | E19: Oversize / Heavy-Haul Recall | F19: Rare-Class Macro Recall
A20: FP32 Baseline Transformer | B20: Mean | C20: =AVERAGE(C5:C7) -> 0.97633333 | D20: =AVERAGE(D5:D7) -> 0.95 | E20: =AVERAGE(E5:E7) -> 0.98055556 | F20: =AVERAGE(F5:F7) -> 0.96527778
A21: FP32 Baseline Transformer | B21: Sample Std Dev | C21: =STDEV(C5:C7)*100 -> 0.17638342 | D21: =STDEV(D5:D7)*100 -> 2.2047928 | E21: =STDEV(E5:E7)*100 -> 1.9245009 | F21: =STDEV(F5:F7)*100 -> 1.8788541
A22: FP32 Linear Attention | B22: Mean | C22: =AVERAGE(C8:C10) -> 0.98188889 | D22: =AVERAGE(D8:D10) -> 0.95 | E22: =AVERAGE(E8:E10) -> 0.98333333 | F22: =AVERAGE(F8:F10) -> 0.96666667
A23: FP32 Linear Attention | B23: Sample Std Dev | C23: =STDEV(C8:C10)*100 -> 0.10183502 | D23: =STDEV(D8:D10)*100 -> 0.83333333 | E23: =STDEV(E8:E10)*100 -> 0.83333333 | F23: =STDEV(F8:F10)*100 -> 0.72168784
A24: Mixed-Precision INT8 Baseline | B24: Mean | C24: =AVERAGE(C11:C13) -> 0.97644444 | D24: =AVERAGE(D11:D13) -> 0.95277778 | E24: =AVERAGE(E11:E13) -> 0.98055556 | F24: =AVERAGE(F11:F13) -> 0.96666667
A25: Mixed-Precision INT8 Baseline | B25: Sample Std Dev | C25: =STDEV(C11:C13)*100 -> 0.19245009 | D25: =STDEV(D11:D13)*100 -> 2.0971762 | E25: =STDEV(E11:E13)*100 -> 1.9245009 | F25: =STDEV(F11:F13)*100 -> 1.9094065
A26: Distilled Student | B26: Mean | C26: =AVERAGE(C14:C16) -> 0.97977778 | D26: =AVERAGE(D14:D16) -> 0.93888889 | E26: =AVERAGE(E14:E16) -> 0.97222222 | F26: =AVERAGE(F14:F16) -> 0.95555556
A27: Distilled Student | B27: Sample Std Dev | C27: =STDEV(C14:C16)*100 -> 0.28349668 | D27: =STDEV(D14:D16)*100 -> 2.9265705 | E27: =STDEV(E14:E16)*100 -> 0.48112522 | F27: =STDEV(F14:F16)*100 -> 1.4632852
A29: Difference from the FP32 baseline, compared with the observed seed spread
A30: Configuration | B30: Metric | C30: Mean Difference vs Baseline (pp) | D30: Seed 0 Difference (pp) | E30: Seed 1 Difference (pp) | F30: Seed 2 Difference (pp) | G30: Baseline Seed Std Dev (pp) | H30: Config Seed Std Dev (pp) | I30: |Difference| / Larger Std Dev | J30: Reading
A31: FP32 Linear Attention | B31: Overall Accuracy | C31: =(C22-C20)*100 -> 0.55555556 | D31: =(C8-C5)*100 -> 0.66666667 | E31: =(C9-C6)*100 -> 0.46666667 | F31: =(C10-C7)*100 -> 0.53333333 | G31: =C21 -> 0.17638342 | H31: =C23 -> 0.10183502 | I31: =ABS(C31)/MAX(G31,H31) -> 3.1497039 | J31: =IF(I31<1,"Smaller than the seed spread: treat as similar","Larger than the seed spread (only 3 seeds; no significance test was run)") -> Larger than the seed spread (only 3 seeds; no significance test was run)
A32: FP32 Linear Attention | B32: Hazmat Recall | C32: =(D22-D20)*100 -> 0 | D32: =(D8-D5)*100 -> 1.6666667 | E32: =(D9-D6)*100 -> 0 | F32: =(D10-D7)*100 -> -1.6666667 | G32: =D21 -> 2.2047928 | H32: =D23 -> 0.83333333 | I32: =ABS(C32)/MAX(G32,H32) -> 0 | J32: =IF(I32<1,"Smaller than the seed spread: treat as similar","Larger than the seed spread (only 3 seeds; no significance test was run)") -> Smaller than the seed spread: treat as similar
A33: FP32 Linear Attention | B33: Oversize / Heavy-Haul Recall | C33: =(E22-E20)*100 -> 0.27777778 | D33: =(E8-E5)*100 -> 1.6666667 | E33: =(E9-E6)*100 -> -0.83333333 | F33: =(E10-E7)*100 -> 0 | G33: =E21 -> 1.9245009 | H33: =E23 -> 0.83333333 | I33: =ABS(C33)/MAX(G33,H33) -> 0.14433757 | J33: =IF(I33<1,"Smaller than the seed spread: treat as similar","Larger than the seed spread (only 3 seeds; no significance test was run)") -> Smaller than the seed spread: treat as similar
A34: FP32 Linear Attention | B34: Rare-Class Macro Recall | C34: =(F22-F20)*100 -> 0.13888889 | D34: =(F8-F5)*100 -> 1.6666667 | E34: =(F9-F6)*100 -> -0.41666667 | F34: =(F10-F7)*100 -> -0.83333333 | G34: =F21 -> 1.8788541 | H34: =F23 -> 0.72168784 | I34: =ABS(C34)/MAX(G34,H34) -> 0.073922127 | J34: =IF(I34<1,"Smaller than the seed spread: treat as similar","Larger than the seed spread (only 3 seeds; no significance test was run)") -> Smaller than the seed spread: treat as similar
A35: Mixed-Precision INT8 Baseline | B35: Overall Accuracy | C35: =(C24-C20)*100 -> 0.011111111 | D35: =(C11-C5)*100 -> 0.033333333 | E35: =(C12-C6)*100 -> 0.033333333 | F35: =(C13-C7)*100 -> -0.033333333 | G35: =C21 -> 0.17638342 | H35: =C25 -> 0.19245009 | I35: =ABS(C35)/MAX(G35,H35) -> 0.057735027 | J35: =IF(I35<1,"Smaller than the seed spread: treat as similar","Larger than the seed spread (only 3 seeds; no significance test was run)") -> Smaller than the seed spread: treat as similar
A36: Mixed-Precision INT8 Baseline | B36: Hazmat Recall | C36: =(D24-D20)*100 -> 0.27777778 | D36: =(D11-D5)*100 -> 0 | E36: =(D12-D6)*100 -> 0.83333333 | F36: =(D13-D7)*100 -> 0 | G36: =D21 -> 2.2047928 | H36: =D25 -> 2.0971762 | I36: =ABS(C36)/MAX(G36,H36) -> 0.12598816 | J36: =IF(I36<1,"Smaller than the seed spread: treat as similar","Larger than the seed spread (only 3 seeds; no significance test was run)") -> Smaller than the seed spread: treat as similar
A37: Mixed-Precision INT8 Baseline | B37: Oversize / Heavy-Haul Recall | C37: =(E24-E20)*100 -> 0 | D37: =(E11-E5)*100 -> 0 | E37: =(E12-E6)*100 -> 0 | F37: =(E13-E7)*100 -> 0 | G37: =E21 -> 1.9245009 | H37: =E25 -> 1.9245009 | I37: =ABS(C37)/MAX(G37,H37) -> 0 | J37: =IF(I37<1,"Smaller than the seed spread: treat as similar","Larger than the seed spread (only 3 seeds; no significance test was run)") -> Smaller than the seed spread: treat as similar
A38: Mixed-Precision INT8 Baseline | B38: Rare-Class Macro Recall | C38: =(F24-F20)*100 -> 0.13888889 | D38: =(F11-F5)*100 -> 0 | E38: =(F12-F6)*100 -> 0.41666667 | F38: =(F13-F7)*100 -> 0 | G38: =F21 -> 1.8788541 | H38: =F25 -> 1.9094065 | I38: =ABS(C38)/MAX(G38,H38) -> 0.072739297 | J38: =IF(I38<1,"Smaller than the seed spread: treat as similar","Larger than the seed spread (only 3 seeds; no significance test was run)") -> Smaller than the seed spread: treat as similar
A39: Distilled Student | B39: Overall Accuracy | C39: =(C26-C20)*100 -> 0.34444444 | D39: =(C14-C5)*100 -> 0.36666667 | E39: =(C15-C6)*100 -> 0.46666667 | F39: =(C16-C7)*100 -> 0.2 | G39: =C21 -> 0.17638342 | H39: =C27 -> 0.28349668 | I39: =ABS(C39)/MAX(G39,H39) -> 1.2149858 | J39: =IF(I39<1,"Smaller than the seed spread: treat as similar","Larger than the seed spread (only 3 seeds; no significance test was run)") -> Larger than the seed spread (only 3 seeds; no significance test was run)
A40: Distilled Student | B40: Hazmat Recall | C40: =(D26-D20)*100 -> -1.1111111 | D40: =(D14-D5)*100 -> -2.5 | E40: =(D15-D6)*100 -> 0 | F40: =(D16-D7)*100 -> -0.83333333 | G40: =D21 -> 2.2047928 | H40: =D27 -> 2.9265705 | I40: =ABS(C40)/MAX(G40,H40) -> 0.3796632 | J40: =IF(I40<1,"Smaller than the seed spread: treat as similar","Larger than the seed spread (only 3 seeds; no significance test was run)") -> Smaller than the seed spread: treat as similar
A41: Distilled Student | B41: Oversize / Heavy-Haul Recall | C41: =(E26-E20)*100 -> -0.83333333 | D41: =(E14-E5)*100 -> 1.6666667 | E41: =(E15-E6)*100 -> -2.5 | F41: =(E16-E7)*100 -> -1.6666667 | G41: =E21 -> 1.9245009 | H41: =E27 -> 0.48112522 | I41: =ABS(C41)/MAX(G41,H41) -> 0.4330127 | J41: =IF(I41<1,"Smaller than the seed spread: treat as similar","Larger than the seed spread (only 3 seeds; no significance test was run)") -> Smaller than the seed spread: treat as similar
A42: Distilled Student | B42: Rare-Class Macro Recall | C42: =(F26-F20)*100 -> -0.97222222 | D42: =(F14-F5)*100 -> -0.41666667 | E42: =(F15-F6)*100 -> -1.25 | F42: =(F16-F7)*100 -> -1.25 | G42: =F21 -> 1.8788541 | H42: =F27 -> 1.4632852 | I42: =ABS(C42)/MAX(G42,H42) -> 0.51745489 | J42: =IF(I42<1,"Smaller than the seed spread: treat as similar","Larger than the seed spread (only 3 seeds; no significance test was run)") -> Smaller than the seed spread: treat as similar
A44: How to read this sheet: a difference below 1.00 in the second-to-last column is smaller than the seed-to-seed spread of the larger of the two models, so it should be treated as similar, not as a real gain or loss.
...

Sheet Per-Class Results
A1: Per-Class Results (mean over seeds 0, 1, 2)
A2: Accuracy per class = recall of that class. Rare classes (Hazmat, Oversize / Heavy Haul) are shaded and each has only 120 test documents: a rare-class decline is shown here even when overall accuracy is unchanged.
A4: Configuration | B4: Class | C4: Test Support | D4: Mean Accuracy / Recall | E4: Seed Std Dev | F4: Change vs FP32 Baseline (pp) | G4: Class Type
A5: FP32 Baseline Transformer | B5: General Dry | C5: 1020 | D5: =AVERAGE(D33:F33) -> 0.97941176 | E5: =STDEV(D33:F33)*100 -> 0.35348542 | F5: =(D5-D5)*100 -> 0 | G5: Common class
A6: FP32 Baseline Transformer | B6: Retail Pallet | C6: 780 | D6: =AVERAGE(D34:F34) -> 0.97307692 | E6: =STDEV(D34:F34)*100 -> 0.33919889 | F6: =(D6-D6)*100 -> 0 | G6: Common class
A7: FP32 Baseline Transformer | B7: Refrigerated | C7: 600 | D7: =AVERAGE(D35:F35) -> 0.98055556 | E7: =STDEV(D35:F35)*100 -> 0.48112522 | F7: =(D7-D7)*100 -> 0 | G7: Common class
A8: FP32 Baseline Transformer | B8: Fragile / High-Value | C8: 360 | D8: =AVERAGE(D36:F36) -> 0.975 | E8: =STDEV(D36:F36)*100 -> 0.73493092 | F8: =(D8-D8)*100 -> 0 | G8: Common class
A9: FP32 Baseline Transformer | B9: Hazmat | C9: 120 | D9: =AVERAGE(D37:F37) -> 0.95 | E9: =STDEV(D37:F37)*100 -> 2.2047928 | F9: =(D9-D9)*100 -> 0 | G9: Rare class (4% of data)
A10: FP32 Baseline Transformer | B10: Oversize / Heavy Haul | C10: 120 | D10: =AVERAGE(D38:F38) -> 0.98055556 | E10: =STDEV(D38:F38)*100 -> 1.9245009 | F10: =(D10-D10)*100 -> 0 | G10: Rare class (4% of data)
A11: FP32 Linear Attention | B11: General Dry | C11: 1020 | D11: =AVERAGE(D39:F39) -> 0.98660131 | E11: =STDEV(D39:F39)*100 -> 0.49345323 | F11: =(D11-D5)*100 -> 0.71895425 | G11: Common class
A12: FP32 Linear Attention | B12: Retail Pallet | C12: 780 | D12: =AVERAGE(D40:F40) -> 0.97991453 | E12: =STDEV(D40:F40)*100 -> 0.41212183 | F12: =(D12-D6)*100 -> 0.68376068 | G12: Common class
A13: FP32 Linear Attention | B13: Refrigerated | C13: 600 | D13: =AVERAGE(D41:F41) -> 0.985 | E13: =STDEV(D41:F41)*100 -> 0.33333333 | F13: =(D13-D7)*100 -> 0.44444444 | G13: Common class
A14: FP32 Linear Attention | B14: Fragile / High-Value | C14: 360 | D14: =AVERAGE(D42:F42) -> 0.97777778 | E14: =STDEV(D42:F42)*100 -> 0.73493092 | F14: =(D14-D8)*100 -> 0.27777778 | G14: Common class
A15: FP32 Linear Attention | B15: Hazmat | C15: 120 | D15: =AVERAGE(D43:F43) -> 0.95 | E15: =STDEV(D43:F43)*100 -> 0.83333333 | F15: =(D15-D9)*100 -> 0 | G15: Rare class (4% of data)
A16: FP32 Linear Attention | B16: Oversize / Heavy Haul | C16: 120 | D16: =AVERAGE(D44:F44) -> 0.98333333 | E16: =STDEV(D44:F44)*100 -> 0.83333333 | F16: =(D16-D10)*100 -> 0.27777778 | G16: Rare class (4% of data)
A17: Mixed-Precision INT8 Baseline | B17: General Dry | C17: 1020 | D17: =AVERAGE(D45:F45) -> 0.97941176 | E17: =STDEV(D45:F45)*100 -> 0.35348542 | F17: =(D17-D5)*100 -> 0 | G17: Common class
A18: Mixed-Precision INT8 Baseline | B18: Retail Pallet | C18: 780 | D18: =AVERAGE(D46:F46) -> 0.97264957 | E18: =STDEV(D46:F46)*100 -> 0.39167314 | F18: =(D18-D6)*100 -> -0.042735043 | G18: Common class
A19: Mixed-Precision INT8 Baseline | B19: Refrigerated | C19: 600 | D19: =AVERAGE(D47:F47) -> 0.98055556 | E19: =STDEV(D47:F47)*100 -> 0.48112522 | F19: =(D19-D7)*100 -> 0 | G19: Common class
A20: Mixed-Precision INT8 Baseline | B20: Fragile / High-Value | C20: 360 | D20: =AVERAGE(D48:F48) -> 0.97592593 | E20: =STDEV(D48:F48)*100 -> 0.69905874 | F20: =(D20-D8)*100 -> 0.092592593 | G20: Common class
A21: Mixed-Precision INT8 Baseline | B21: Hazmat | C21: 120 | D21: =AVERAGE(D49:F49) -> 0.95277778 | E21: =STDEV(D49:F49)*100 -> 2.0971762 | F21: =(D21-D9)*100 -> 0.27777778 | G21: Rare class (4% of data)
A22: Mixed-Precision INT8 Baseline | B22: Oversize / Heavy Haul | C22: 120 | D22: =AVERAGE(D50:F50) -> 0.98055556 | E22: =STDEV(D50:F50)*100 -> 1.9245009 | F22: =(D22-D10)*100 -> 0 | G22: Rare class (4% of data)
A23: Distilled Student | B23: General Dry | C23: 1020 | D23: =AVERAGE(D51:F51) -> 0.98496732 | E23: =STDEV(D51:F51)*100 -> 0.49345323 | F23: =(D23-D5)*100 -> 0.55555556 | G23: Common class
A24: Distilled Student | B24: Retail Pallet | C24: 780 | D24: =AVERAGE(D52:F52) -> 0.98162393 | E24: =STDEV(D52:F52)*100 -> 0.074019265 | F24: =(D24-D6)*100 -> 0.85470085 | G24: Common class
A25: Distilled Student | B25: Refrigerated | C25: 600 | D25: =AVERAGE(D53:F53) -> 0.98111111 | E25: =STDEV(D53:F53)*100 -> 0.69388867 | F25: =(D25-D7)*100 -> 0.055555556 | G25: Common class
A26: Distilled Student | B26: Fragile / High-Value | C26: 360 | D26: =AVERAGE(D54:F54) -> 0.975 | E26: =STDEV(D54:F54)*100 -> 0.48112522 | F26: =(D26-D8)*100 -> 0 | G26: Common class
A27: Distilled Student | B27: Hazmat | C27: 120 | D27: =AVERAGE(D55:F55) -> 0.93888889 | E27: =STDEV(D55:F55)*100 -> 2.9265705 | F27: =(D27-D9)*100 -> -1.1111111 | G27: Rare class (4% of data)
A28: Distilled Student | B28: Oversize / Heavy Haul | C28: 120 | D28: =AVERAGE(D56:F56) -> 0.97222222 | E28: =STDEV(D56:F56)*100 -> 0.48112522 | F28: =(D28-D10)*100 -> -0.83333333 | G28: Rare class (4% of data)
A30: Seed Std Dev is the sample standard deviation (pp) over three seeds. Compare each change with it, and with the 0.83 pp size of one rare-class document, before reading a difference as real.
A31: Source values per seed (correct documents / test support; click a cell to see the counts)
A32: Configuration | B32: Class | C32: Test Support | D32: Seed 0 | E32: Seed 1 | F32: Seed 2 | G32: Source
A33: FP32 Baseline Transformer | B33: General Dry | C33: 1020 | D33: =1000/1020 -> 0.98039216 | E33: =1002/1020 -> 0.98235294 | F33: =995/1020 -> 0.9754902 | G33: bol_experiment_cuda_run_v4_benchmark.ipynb, cell 14
A34: FP32 Baseline Transformer | B34: Retail Pallet | C34: 780 | D34: =758/780 -> 0.97179487 | E34: =762/780 -> 0.97692308 | F34: =757/780 -> 0.97051282 | G34: bol_experiment_cuda_run_v4_benchmark.ipynb, cell 14
A35: FP32 Baseline Transformer | B35: Refrigerated | C35: 600 | D35: =590/600 -> 0.98333333 | E35: =590/600 -> 0.98333333 | F35: =585/600 -> 0.975 | G35: bol_experiment_cuda_run_v4_benchmark.ipynb, cell 14
A36: FP32 Baseline Transformer | B36: Fragile / High-Value | C36: 360 | D36: =350/360 -> 0.97222222 | E36: =349/360 -> 0.96944444 | F36: =354/360 -> 0.98333333 | G36: bol_experiment_cuda_run_v4_benchmark.ipynb, cell 14
A37: FP32 Baseline Transformer | B37: Hazmat | C37: 120 | D37: =112/120 -> 0.93333333 | E37: =113/120 -> 0.94166667 | F37: =117/120 -> 0.975 | G37: bol_experiment_cuda_run_v4_benchmark.ipynb, cell 14
A38: FP32 Baseline Transformer | B38: Oversize / Heavy Haul | C38: 120 | D38: =115/120 -> 0.95833333 | E38: =119/120 -> 0.99166667 | F38: =119/120 -> 0.99166667 | G38: bol_experiment_cuda_run_v4_benchmark.ipynb, cell 14
A39: FP32 Linear Attention | B39: General Dry | C39: 1020 | D39: =1011/1020 -> 0.99117647 | E39: =1007/1020 -> 0.9872549 | F39: =1001/1020 -> 0.98137255 | G39: bol_experiment_cuda_run_v4_benchmark.ipynb, cell 23
A40: FP32 Linear Attention | B40: Retail Pallet | C40: 780 | D40: =763/780 -> 0.97820513 | E40: =768/780 -> 0.98461538 | F40: =762/780 -> 0.97692308 | G40: bol_experiment_cuda_run_v4_benchmark.ipynb, cell 23
A41: FP32 Linear Attention | B41: Refrigerated | C41: 600 | D41: =591/600 -> 0.985 | E41: =589/600 -> 0.98166667 | F41: =593/600 -> 0.98833333 | G41: bol_experiment_cuda_run_v4_benchmark.ipynb, cell 23
A42: FP32 Linear Attention | B42: Fragile / High-Value | C42: 360 | D42: =349/360 -> 0.96944444 | E42: =354/360 -> 0.98333333 | F42: =353/360 -> 0.98055556 | G42: bol_experiment_cuda_run_v4_benchmark.ipynb, cell 23
...

Sheet Raw Benchmark Runs
A1: Raw Benchmark Runs: every timed trial
A2: Source: results/benchmark_raw_latency.csv. Batch size 1, sequence length 128, 15 untimed warm-ups then 100 timed trials per run, CUDA synchronize before and after each forward. Run 2 is the baseline repeat used for the stability check.
A4: Configuration | B4: Benchmark Run | C4: Trial Number | D4: Test Example Index | E4: Latency ms | F4: Document Position (0-99)
A5: FP32 Baseline Transformer | B5: 1 | C5: 1 | D5: 1750 | E5: 5.822118 | F5: 0
A6: FP32 Baseline Transformer | B6: 1 | C6: 2 | D6: 98 | E6: 5.49166 | F6: 1
A7: FP32 Baseline Transformer | B7: 1 | C7: 3 | D7: 141 | E7: 5.322058 | F7: 2
A8: FP32 Baseline Transformer | B8: 1 | C8: 4 | D8: 2106 | E8: 4.940854 | F8: 3
A9: FP32 Baseline Transformer | B9: 1 | C9: 5 | D9: 1242 | E9: 5.12706 | F9: 4
A10: FP32 Baseline Transformer | B10: 1 | C10: 6 | D10: 993 | E10: 5.248679 | F10: 5
A11: FP32 Baseline Transformer | B11: 1 | C11: 7 | D11: 995 | E11: 5.052497 | F11: 6
A12: FP32 Baseline Transformer | B12: 1 | C12: 8 | D12: 663 | E12: 5.246636 | F12: 7
A13: FP32 Baseline Transformer | B13: 1 | C13: 9 | D13: 37 | E13: 5.230171 | F13: 8
A14: FP32 Baseline Transformer | B14: 1 | C14: 10 | D14: 4 | E14: 5.107523 | F14: 9
A15: FP32 Baseline Transformer | B15: 1 | C15: 11 | D15: 2311 | E15: 5.02996 | F15: 10
A16: FP32 Baseline Transformer | B16: 1 | C16: 12 | D16: 289 | E16: 5.238368 | F16: 11
... A504: FP32 Baseline Transformer | B504: 2 | C504: 100 | D504: 1710 | E504: 4.979446 | F504: 99

Sheet Benchmark Detail
A1: Benchmark Detail
A2: Tesla T4 (compute capability 7.5), batch size 1, sequence length 128, seed-0 models, 15 warm-up and 100 timed trials. Latency columns are formulas over the Raw Benchmark Runs sheet.
A4: Configuration | B4: Benchmark Run | C4: p50 Latency ms | D4: p95 Latency ms | E4: Mean Latency ms | F4: Minimum Latency ms | G4: Maximum Latency ms | H4: Resident GPU Memory MB | I4: Peak GPU Memory MB (primary) | J4: Incremental Peak Memory MB | K4: Weight Storage MB | L4: Total Parameters | M4: Non-Embedding Parameters | N4: Background Allocated Before Load MB (diagnostic) | O4: Peak Minus Background MB (diagnostic)
A5: FP32 Baseline Transformer | B5: 1 | C5: =PERCENTILE('Raw Benchmark Runs'!$E$5:$E$104,0.5) -> 5.227631 | D5: =PERCENTILE('Raw Benchmark Runs'!$E$5:$E$104,0.95) -> 6.5318771 | E5: =AVERAGE('Raw Benchmark Runs'!$E$5:$E$104) -> 5.4502464 | F5: =MIN('Raw Benchmark Runs'!$E$5:$E$104) -> 4.896878 | G5: =MAX('Raw Benchmark Runs'!$E$5:$E$104) -> 9.97385 | H5: 69.96582 | I5: 75.402832 | J5: =I5-H5 -> 5.4370117 | K5: 4.8051987 | L5: 1259654 | M5: 530950 | N5: 65.0625 | O5: =I5-N5 -> 10.340332
A6: FP32 Linear Attention | B6: 1 | C6: =PERCENTILE('Raw Benchmark Runs'!$E$105:$E$204,0.5) -> 6.9316315 | D6: =PERCENTILE('Raw Benchmark Runs'!$E$105:$E$204,0.95) -> 8.2889259 | E6: =AVERAGE('Raw Benchmark Runs'!$E$105:$E$204) -> 7.1350006 | F6: =MIN('Raw Benchmark Runs'!$E$105:$E$204) -> 6.461409 | G6: =MAX('Raw Benchmark Runs'!$E$105:$E$204) -> 11.841704 | H6: 69.96582 | I6: 75.402832 | J6: =I6-H6 -> 5.4370117 | K6: 4.8051987 | L6: 1259654 | M6: 530950 | N6: 65.0625 | O6: =I6-N6 -> 10.340332
A7: Mixed-Precision INT8 Baseline | B7: 1 | C7: =PERCENTILE('Raw Benchmark Runs'!$E$205:$E$304,0.5) -> 11.474539 | D7: =PERCENTILE('Raw Benchmark Runs'!$E$205:$E$304,0.95) -> 13.280214 | E7: =AVERAGE('Raw Benchmark Runs'!$E$205:$E$304) -> 11.713739 | F7: =MIN('Raw Benchmark Runs'!$E$205:$E$304) -> 10.892761 | G7: =MAX('Raw Benchmark Runs'!$E$205:$E$304) -> 17.383112 | H7: 68.479492 | I7: 73.912598 | J7: =I7-H7 -> 5.4331055 | K7: 3.3120346 | L7: 1259654 | M7: 530950 | N7: 65.0625 | O7: =I7-N7 -> 8.8500977
A8: Distilled Student | B8: 1 | C8: =PERCENTILE('Raw Benchmark Runs'!$E$305:$E$404,0.5) -> 2.845486 | D8: =PERCENTILE('Raw Benchmark Runs'!$E$305:$E$404,0.95) -> 3.3737753 | E8: =AVERAGE('Raw Benchmark Runs'!$E$305:$E$404) -> 2.9339611 | F8: =MIN('Raw Benchmark Runs'!$E$305:$E$404) -> 2.619099 | G8: =MAX('Raw Benchmark Runs'!$E$305:$E$404) -> 4.527425 | H8: 66.812012 | I8: 69.53125 | J8: =I8-H8 -> 2.7192383 | K8: 1.6472397 | L8: 431814 | M8: 67462 | N8: 65.0625 | O8: =I8-N8 -> 4.46875
A9: FP32 Baseline Transformer (repeat run for stability check) | B9: 2 | C9: =PERCENTILE('Raw Benchmark Runs'!$E$405:$E$504,0.5) -> 4.941679 | D9: =PERCENTILE('Raw Benchmark Runs'!$E$405:$E$504,0.95) -> 7.1141127 | E9: =AVERAGE('Raw Benchmark Runs'!$E$405:$E$504) -> 5.2015266 | F9: =MIN('Raw Benchmark Runs'!$E$405:$E$504) -> 4.650847 | G9: =MAX('Raw Benchmark Runs'!$E$405:$E$504) -> 9.176203 | H9: 69.96582 | I9: 75.402832 | J9: =I9-H9 -> 5.4370117 | K9: 4.8051987 | L9: 1259654 | M9: 530950 | N9: 65.0625 | O9: =I9-N9 -> 10.340332
A11: Baseline repeatability check (stability check only; Run 1 is the reported benchmark value)
A12: Metric | C12: Run 1 (ms) | D12: Run 2 (ms) | E12: % Difference | F12: Threshold | G12: Within Threshold?
A13: p50 latency | C13: =C5 -> 5.227631 | D13: =C9 -> 4.941679 | E13: =ABS(D13-C13)/C13 -> 0.054700112 | F13: 0.15 | G13: =IF(E13<=F13,"Yes","No: timing flagged unstable") -> Yes
A14: p95 latency | C14: =D5 -> 6.5318771 | D14: =D9 -> 7.1141127 | E14: =ABS(D14-C14)/C14 -> 0.089137554 | F14: 0.15 | G14: =IF(E14<=F14,"Yes","No: timing flagged unstable") -> Yes
A15: Both baseline runs stayed within the predetermined 15% stability threshold (p50 differs by 5.47%, p95 by 8.91%), so the latency comparison is treated as final.
A17: Timing note: every run contains a few short bursts of trials at roughly 1.5 to 2 times its own median latency (more than 1.5x the run median: baseline run 1 = 4 trials, linear attention = 3, INT8 = 1, student = 3, baseline run 2 = 5). They appear in consecutive trials, which is typical of transient interference on shared hardware. They barely move p50 (the baseline run 1 p50 changes from 5.228 to 5.215 ms if they are excluded) but do move p95 (baseline run 1: 6.532 to 5.760 ms). No trial was removed from any reported number; this is a sensitivity note only. p50 is the more robust comparison metric.
A18: Memory note: Resident, Peak and Incremental values are PyTorch GPU allocator memory (1 MB = 1,048,576 bytes); they do not include the CUDA context or other driver-level memory. A constant 65.0625 MB was already allocated before each model was loaded (identical for all five runs; its origin was not isolated, though it is consistent with library workspaces). Peak GPU Memory is the primary deployment-memory metric. Resident and Incremental Peak are supporting diagnostics, and the two background-subtracted columns are diagnostic only: they isolate the model-plus-inference footprint and are not a deployment-memory figure.

Sheet Scaling Law
A1: Scaling Law: compute estimates
A2: N = non-embedding parameters (total parameters shown for context only). Counted quantities come from the experiment; every FLOP figure and every projection is a formula-based estimate, not a measurement.
B4: MEASURED / COUNTED | E4: FORMULA-BASED ESTIMATES (6ND and D = 20N): NOT MEASUREMENTS
A5: Configuration | B5: Total Parameters | C5: Non-Embedding Parameters N | D5: Actual Training Tokens | E5: Estimated Actual Training FLOPs (6ND) | F5: Compute-Optimal Tokens (D = 20N) | G5: Compute-Optimal Training FLOPs (C = 6ND) | H5: 10x Non-Embedding Parameters | I5: 10x Compute-Optimal Tokens | J5: 10x Training FLOPs | K5: Compute Multiple | L5: Notes
A6: FP32 Baseline Transformer | B6: 1259654 | C6: 530950 | D6: 10752000 | E6: =6*C6*D6 -> 34252646400000 | F6: =20*C6 -> 10619000 | G6: =6*C6*F6 -> 33828948300000 | H6: =10*C6 -> 5309500 | I6: =20*H6 -> 106190000 | J6: =6*H6*I6 -> 3.3828948e+15 | K6: =J6/G6 -> 100 | L6: Actual D = padded positions (10,752,000); actual D is 1.01x the compute-optimal D (counts 8 repeated epochs).
A7: FP32 Linear Attention | B7: 1259654 | C7: 530950 | D7: 10752000 | E7: =6*C7*D7 -> 34252646400000 | F7: =20*C7 -> 10619000 | G7: =6*C7*F7 -> 33828948300000 | H7: =10*C7 -> 5309500 | I7: =20*H7 -> 106190000 | J7: =6*H7*I7 -> 3.3828948e+15 | K7: =J7/G7 -> 100 | L7: Same N and same training workload as the baseline, so identical 6ND values. 6ND does not capture linear attention's different attention cost.
A8: Mixed-Precision INT8 Baseline | B8: 1259654 | C8: 530950 | D8: 10752000 | E8: =6*C8*D8 -> 34252646400000 | F8: =20*C8 -> 10619000 | G8: =6*C8*F8 -> 33828948300000 | H8: =10*C8 -> 5309500 | I8: =20*H8 -> 106190000 | J8: =6*H8*I8 -> 3.3828948e+15 | K8: =J8/G8 -> 100 | L8: Post-training INT8 quantization of the trained FP32 baseline: training compute is the baseline's own (not reduced by INT8 storage). Quantization changes the inference representation, not the original training compute. Projection rows refer to the underlying baseline architecture.
A9: Distilled Student | B9: 431814 | C9: 67462 | D9: 10752000 | E9: =6*C9*D9 -> 4352108544000 | F9: =20*C9 -> 1349240 | G9: =6*C9*F9 -> 546134573280 | H9: =10*C9 -> 674620 | I9: =20*H9 -> 13492400 | J9: =6*H9*I9 -> 54613457328000 | K9: =J9/G9 -> 100 | L9: Student's own 6ND only. Excludes teacher inference for soft targets and the cost of training the teacher first (see the baseline row). Actual D is 7.97x its compute-optimal D.
A11: Readable view (same estimates; TFLOP = 10^12, PFLOP = 10^15, GFLOP = 10^9 floating-point operations)
A12: Configuration | B12: Actual Training FLOPs | C12: Compute-Optimal FLOPs | D12: 10x Training FLOPs | E12: Actual / Compute-Optimal Tokens
A13: FP32 Baseline Transformer | B13: 34.25 TFLOP | C13: 33.83 TFLOP | D13: 3.38 PFLOP | E13: 1.01x
A14: FP32 Linear Attention | B14: 34.25 TFLOP | C14: 33.83 TFLOP | D14: 3.38 PFLOP | E14: 1.01x
A15: Mixed-Precision INT8 Baseline | B15: 34.25 TFLOP | C15: 33.83 TFLOP | D15: 3.38 PFLOP | E15: 1.01x
A16: Distilled Student | B16: 4.35 TFLOP | C16: 546.13 GFLOP | D16: 54.61 TFLOP | E16: 7.97x
A18: Method and notes
A19: Training workload (identical for the baseline, linear-attention and student runs): 10,500 documents x 128 positions x 8 epochs = 10,752,000 padded sequence positions. D uses padded positions because the GPU computed on all 128 positions of every document; non-padding tokens would be 3,661,328 (2.94x fewer). D counts 8 repeated epochs, not unique tokens.
A20: Post-training INT8 does not reduce the original baseline training FLOPs: the INT8 model was produced from the already trained FP32 baseline, so its row shows the baseline's training compute. Quantization changes the inference representation, not the original training compute.
A21: The distilled student's basic 6ND calculation does not include teacher-inference cost. Teacher-logit caching for the student (one forward pass over train and validation documents per seed) was measured at 1.2, 1.2, 1.3 s for seeds 0, 1, 2 (printed to one decimal); a formula-based forward-only estimate is 1.631e+12 FLOPs per seed. Neither is added to the student's 6ND figure, and the student also required the baseline teacher to be trained first.
A22: The 10x projection is an estimate (N_10x = 10N, D_10x = 20 N_10x, C_10x = 6 N_10x D_10x). The compute multiple is calculated as C_10x / C_compute-optimal, and it is about 100x because parameters and the compute-optimal token budget both grow 10x. These are not measured training runs.
A23: Scaling may change GPU utilization, and larger matrix multiplications may use the hardware more efficiently, so FLOPs would not translate linearly into wall-clock time.
A24: A larger model may exceed single-GPU memory. Gradient checkpointing or smaller batches could then change the wall-clock cost.
A25: Longer sequence lengths would change attention cost, which 6ND does not model. Multi-GPU scaling would introduce communication overhead.
A26: The 20-tokens-per-parameter relationship is a rule of thumb and may not be optimal for this synthetic classification workload. 6ND also ignores attention-score FLOPs, embeddings, LayerNorm, the optimizer and the per-epoch validation passes.
A27: Scaling-law figures are not used to rank the models.
A28: Provenance: results/scaling_law_results.csv and .json, produced by the notebook's Part 6 cell from the counts printed in the executed notebooks (parameter counts, 10,500 training documents, 8 epochs, length 128). The cells in this sheet are formulas that reproduce the CSV values exactly.

Sheet Methodology
A1: Methodology and Known Limitations
A2: A concise record of how the results were produced. Source files are named for every item.
A4: Dataset
A5: Dataset | B5: Synthetic bill-of-lading text generated by a seeded script (data seed 42), not Brightline production data. | C5: bol_experiment.ipynb, Part 1 data cell
A6: Size and split | B6: 15,000 documents: 10,500 train / 1,500 validation / 3,000 test (70% / 10% / 20%), stratified by class. | C6: bol_experiment_cuda_run_v4_benchmark.ipynb, cell 5 output
A7: Classes | B7: Six: General Dry (34%), Retail Pallet (26%), Refrigerated (20%), Fragile / High-Value (12%), Hazmat (4%), Oversize / Heavy Haul (4%). | C7: bol_experiment.ipynb, Part 1 data cell
A8: Rare classes | B8: Hazmat and Oversize / Heavy Haul, 4% each. Test support 120 documents each; training counts 472 and 466. | C8: bol_experiment_cuda_run_v4_benchmark.ipynb, cell 5 output
A9: Training-only label noise | B9: 3% of training labels were flipped to a different random class (307 of 10,500 = 2.92%). Validation and test labels are clean (verified by regenerating the data without noise). | C9: bol_experiment_cuda_run_v4_benchmark.ipynb, cell 5 and verification-check outputs
A10: Input-level corruption (train, validation and test) | B10: OCR character substitutions and drops (per-document error rate 0%, 1%, 3% or 6%), missing class-specific fields (25% each), missing commodity line (5%), conflicting instruction borrowed from another class (15%), truncated values (6%), irregular spacing. Corruption never changes the label. | C10: bol_experiment.ipynb, Part 1 constants
A11: Dataset SHA-256 | B11: e74c4242ce78d13fec8ad56ebe0647c6598766c815068a00ccb2369c6307d610 | C11: bol_experiment_cuda_run_v4_benchmark.ipynb, cell 5 output; verified identical in every configuration run
A12: Tokenizer and models
A13: Tokenizer | B13: Lowercase; split into alphanumeric runs and single punctuation marks; vocabulary built from training texts only (minimum frequency 2); padding id 0, unknown id 1. | C13: bol_experiment.ipynb, Part 1 tokenizer cell
A14: Vocabulary and length | B14: Vocabulary size 5,565. Fixed sequence length 128. Mean document length 43.6 tokens (maximum 72), nothing truncated, so about 66% of positions are padding. Unknown-token rate 6.4% on test. | C14: bol_experiment_cuda_run_v4_benchmark.ipynb, cell 7 output
A15: FP32 Baseline Transformer | B15: Token + learned position embeddings, 4 pre-LN blocks (d_model 128, 4 heads, feed-forward 256, GELU), padding-aware softmax attention, mean pooling over non-padding tokens, 6-class linear head. 1,259,654 parameters (530,950 non-embedding). | C15: bol_experiment.ipynb, Part 1 model cell
A16: FP32 Linear Attention | B16: Same network with softmax attention replaced by non-causal linear attention using phi(x) = ELU(x) + 1; padded keys and values are zeroed; no T x T matrix is built; identical parameter count (1,259,654). Verified against an explicit masked reference and a padding-invariance test. | C16: bol_experiment.ipynb, Part 2
A17: INT8 method | B17: Post-training INT8 with bitsandbytes LLM.int8 (Linear8bitLt, outlier threshold 6.0, no calibration data) applied to the trained FP32 baseline checkpoints. 16 hidden Linear layers are INT8 (99.85% of Linear weights); activations are cast to FP16 inside those layers. | C17: bol_experiment.ipynb, Part 3
A18: FP32 classification-head limitation | B18: The six-output head (128 -> 6) stayed FP32 because the bitsandbytes INT8 path failed for that shape on the Tesla T4 with a cuBLASLt runtime error (ldc = 6). The 128 -> 128, 128 -> 256, 128 -> 384 and 256 -> 128 shapes passed. The model is therefore a mixed-precision configuration, not fully INT8; embeddings and LayerNorm also stay FP32. | C18: bol_experiment_cuda_run_v4_benchmark.ipynb, cell 28 output
A19: Distilled student | B19: d_model 64, 2 layers, 2 heads, feed-forward 128; same vocabulary, tokenizer, length 128, pre-LN structure, padding-aware attention and pooling. 431,814 parameters (67,462 non-embedding). | C19: bol_experiment_cuda_run_v4_benchmark.ipynb, cell 34 output
A20: Knowledge distillation | B20: Teacher = the FP32 baseline of the same seed. Loss = 0.5 x cross-entropy(student, noisy training labels) + 0.5 x T^2 x KL(teacher || student), T = 2, KL with batchmean reduction on temperature-softened distributions. Teacher logits were cached for train and validation only, with the teacher in eval mode, no gradients; the test set was never used for distillation. | C20: bol_experiment.ipynb, Part 4
A21: Training protocol
A22: Optimizer and schedule | B22: AdamW, learning rate 1e-3, weight decay 0.01, 100 warm-up steps then linear decay to zero, batch size 64, 8 epochs, FP32, plain cross-entropy (no class weights). | C22: bol_experiment.ipynb, Part 1 training cell
A23: Seeds | B23: Training seeds 0, 1, 2 for every trained model (INT8 is derived from each baseline seed). Dataset seed 42. Benchmark document-selection seed 2025. | C23: bol_experiment.ipynb
A24: Evaluation policy | B24: Final-epoch model is evaluated; validation accuracy is only monitored. The test set is evaluated once per model after training and never used for selection, calibration or distillation. | C24: bol_experiment.ipynb, training cells and verification checks
A25: Hardware and software
A26: GPU | B26: Tesla T4, compute capability 7.5, one Google Colab session. | C26: results/benchmark_meta.json
A27: Software | B27: PyTorch 2.11.0+cu130, CUDA 13.0, bitsandbytes 0.50.2, Python 3.13.15. | C27: results/benchmark_meta.json
A28: Determinism | B28: Seeds fixed in Python, NumPy and PyTorch; cuDNN deterministic mode and torch.use_deterministic_algorithms(True, warn_only=True) requested. CUDA execution is not guaranteed to be bitwise deterministic: PyTorch warned that the softmax-attention backward pass uses a non-deterministic kernel, so exact GPU reruns may differ slightly. | C28: bol_experiment_cuda_run_v4_benchmark.ipynb, training cell warning output
A29: Benchmark protocol
A30: Workload | B30: Batch size 1, sequence length 128 (input shape 1 x 128), the same 100 test documents in the same order for every model (seeded index list, sha256 dd8d838a7ee2ee6d). model.eval(), torch.no_grad(), no autocast beyond what the INT8 layers do internally. Seed-0 models. | C30: results/benchmark_meta.json
A31: Warm-up, trials, synchronization | B31: 15 untimed warm-up forwards, then torch.cuda.synchronize(); 100 timed trials, each: synchronize, start time.perf_counter(), one forward pass, synchronize, stop. Model loading, tokenization, CPU-to-GPU transfer and warm-up were not timed. p50 and p95 use numpy percentile (linear interpolation). | C31: results/benchmark_raw_latency.csv, benchmark_meta.json
A32: Peak-memory method | B32: Before each model: previous model deleted, gc.collect(), torch.cuda.empty_cache(), synchronize. After loading the new model on CUDA: torch.cuda.reset_peak_memory_stats(), resident = torch.cuda.memory_allocated(), then warm-up and timed trials, then peak = torch.cuda.max_memory_allocated(). PyTorch allocator memory only; it excludes the CUDA context and driver memory. A constant 65.0625 MB was allocated before every model was loaded. | C32: results/benchmark_meta.json, benchmark_memory_diagnostics.csv
A33: Baseline repeatability test | B33: The FP32 baseline was benchmarked twice (first, and again after the other three models). p50 differed by 5.47% and p95 by 8.91% against a predetermined 15% threshold: both within the threshold. | C33: results/benchmark_meta.json
A34: Why latency uses one seed | B34: Latency and memory use seed 0. Across seeds the architecture, tensor shapes, precision and execution path are unchanged, so repeated latency trials on one representative trained seed are used while seed-to-seed variation is measured for quality (three seeds). | C34: Benchmark design
A35: Known limitations
A36: Limitation 1 | B36: Synthetic data may not represent real Brightline traffic, document layouts or error patterns.
A37: Limitation 2 | B37: Only one GPU type was benchmarked (Tesla T4). Android tablet hardware and runtimes were not tested; bitsandbytes INT8 is a CUDA-GPU method.
A38: Limitation 3 | B38: Shared Colab hardware can introduce timing variation. Short bursts of slower trials appeared in every run and mainly affect p95, which is why p50 is the more robust comparison.
A39: Limitation 4 | B39: CUDA execution is not guaranteed to be bitwise deterministic.
A40: Limitation 5 | B40: Sequence length was fixed at 128 (documents average about 44 tokens, so most positions are padding).
A41: Limitation 6 | B41: Linear attention may have different relative performance at longer sequences; that was not measured.
...

Sheet Recommendation
A1: Recommendation
A2: Evidence-based qualitative ranking. No hidden weighted score is used. Differences inside the observed seed variation are described as similar, not as wins or losses.
A4: Ranking
A5: Rank | B5: Configuration | C5: Why it ranks here | D5: What Brightline gains | E5: What Brightline gives up | F5: Residual risk
A6: 1 | B6: Distilled Student | C6: Best on every efficiency measure: p50 -45.6%, p95 -48.3%, peak GPU memory -7.8%, weight storage -65.7%, parameters -65.7% versus the baseline, with overall accuracy not lower (97.98% vs 97.63%, +0.34 pp). Its rare-class macro recall is 0.97 pp lower, but that gap is 0.52 of the larger seed spread, so it is possible but not confirmed. | D6: The smallest and fastest model, with headroom for slower tablet hardware and the same architecture family as the baseline (no special runtime). | E6: About one percentage point of mean rare-class macro recall (hazmat 93.9% vs 95.0%); that is 7 more missed rare documents out of 720 across three seeds. It also needs a trained teacher and a distillation step. | F6: Rare-class (hazmat, oversize / heavy-haul) performance on real Brightline documents is unverified; the measured decline sits inside seed variation, but every paired seed was lower. Synthetic data, one GPU type, 120 test documents per rare class.
A7: 2 | B7: FP32 Baseline Transformer | C7: The reference configuration: simplest and established, with similar overall accuracy (97.63%). It ranks above Linear Attention and INT8 because it is faster than both while their quality is similar to or only slightly better than its own; it ranks below the student because it needs about 2.9x the weight storage and 1.9x the p95 latency for no measured accuracy advantage. | D7: Simple, established behavior with no compression, custom attention or distillation; the natural fallback if rare-class validation of the student fails. | E7: Larger weights (4.81 MB), higher p95 latency (6.53 ms) and higher peak GPU memory (75.40 MB, tied with Linear Attention) than the student. | F7: Same synthetic-data and rare-class sampling limits; its rare-class recall varies by 1.88 pp (std dev) across seeds.
A8: 3 | B8: FP32 Linear Attention | C8: Highest mean overall accuracy (98.19%, +0.56 pp; above every baseline seed, 3.1x the larger seed spread). But at sequence length 128 it was slower than the baseline (p50 +32.6%, p95 +26.9%) and did not reduce memory or storage; rare-class recall is similar within seed variation. Ranks 2 and 3 are a close judgment: Linear Attention is the better choice only if a half-point of accuracy is worth about a quarter more latency. | D8: The highest measured overall accuracy and an attention cost that grows linearly with length (benefit at longer sequences was not tested). | E8: About 1.8 ms more p95 latency than the baseline and no savings in weights (4.81 MB) or peak memory. | F8: Behavior at longer sequences was not measured; custom attention code to maintain; the accuracy edge is small and rare-class results did not improve beyond seed variation.
A9: 4 | B9: Mixed-Precision INT8 Baseline | C9: Accuracy is unchanged (97.64%, +0.01 pp) and weights are 31.1% smaller, but it was the slowest model on the T4 (p50 +119.5%, p95 +103.3%) and peak GPU memory fell only 2.0%. The storage gain is limited because embeddings and the head stay FP32. | D9: A smaller weight file (3.31 MB) with no accuracy loss. | E9: More than double the baseline's latency; a mixed-precision configuration because the 6-class head could not run in INT8; a dependency on bitsandbytes. | F9: bitsandbytes INT8 is a CUDA-GPU path; Android tablet inference would need a different runtime, and the speed benefit was not demonstrated even on the T4.
A11: Final recommendation for Sandra
A12: Ship the Distilled Student: on the Tesla T4 it cut model weight storage by 65.7% and p95 latency by 48.3% versus the FP32 baseline while overall accuracy stayed similar (97.98% vs 97.63%, a small measured difference). The main residual risk Sandra is accepting is a possible rare-class trade-off, because mean rare-class macro recall was 95.56% vs 96.53% (about one point lower, smaller than the baseline's seed-to-seed spread and therefore not confirmed). Before full rollout, check hazmat and oversize / heavy-haul recall on real Brightline documents and keep the FP32 baseline as the fallback.
A14: Evidence by criterion (values link to the Trade-off Board and Quality by Seed sheets; no weights are applied)
B15: Criterion | C15: FP32 Baseline Transformer | D15: FP32 Linear Attention | E15: Mixed-Precision INT8 Baseline | F15: Distilled Student | G15: Reading
B16: Overall accuracy mean | C16: ='Trade-off Board'!G5 -> 0.97633333 | D16: ='Trade-off Board'!G6 -> 0.98188889 | E16: ='Trade-off Board'!G7 -> 0.97644444 | F16: ='Trade-off Board'!G8 -> 0.97977778 | G16: Linear Attention highest; the others are within about half a point of one another (see seed-spread rows).
B17: Rare-class macro recall | C17: ='Trade-off Board'!J5 -> 0.96527778 | D17: ='Trade-off Board'!J6 -> 0.96666667 | E17: ='Trade-off Board'!J7 -> 0.96666667 | F17: ='Trade-off Board'!J8 -> 0.95555556 | G17: Student lowest; the gap to the baseline is smaller than the baseline's seed spread.
B18: p50 latency ms | C18: ='Trade-off Board'!M5 -> 5.227631 | D18: ='Trade-off Board'!M6 -> 6.9316315 | E18: ='Trade-off Board'!M7 -> 11.474539 | F18: ='Trade-off Board'!M8 -> 2.845486 | G18: Student fastest; INT8 slowest.
B19: p95 latency ms | C19: ='Trade-off Board'!N5 -> 6.5318771 | D19: ='Trade-off Board'!N6 -> 8.2889259 | E19: ='Trade-off Board'!N7 -> 13.280214 | F19: ='Trade-off Board'!N8 -> 3.3737753 | G19: Same ordering as p50; p95 is more sensitive to transient timing spikes.
B20: Peak GPU memory MB | C20: ='Trade-off Board'!P5 -> 75.402832 | D20: ='Trade-off Board'!P6 -> 75.402832 | E20: ='Trade-off Board'!P7 -> 73.912598 | F20: ='Trade-off Board'!P8 -> 69.53125 | G20: Includes a constant pre-existing allocation; the spread between rows is small.
B21: Weight storage MB | C21: ='Trade-off Board'!E5 -> 4.8051987 | D21: ='Trade-off Board'!E6 -> 4.8051987 | E21: ='Trade-off Board'!E7 -> 3.3120346 | F21: ='Trade-off Board'!E8 -> 1.6472397 | G21: Student smallest; INT8 limited by FP32 embeddings.
B22: Total parameters | C22: ='Trade-off Board'!C5 -> 1259654 | D22: ='Trade-off Board'!C6 -> 1259654 | E22: ='Trade-off Board'!C7 -> 1259654 | F22: ='Trade-off Board'!C8 -> 431814 | G22: Quantization and linear attention do not change the parameter count.
B23: Overall accuracy difference vs baseline / larger seed std | C23: reference | D23: ='Quality by Seed'!I31 -> 3.1497039 | E23: ='Quality by Seed'!I35 -> 0.057735027 | F23: ='Quality by Seed'!I39 -> 1.2149858 | G23: Above 1.00 = larger than the seed spread (3 seeds, not a significance test).
B24: Rare-class recall difference vs baseline / larger seed std | C24: reference | D24: ='Quality by Seed'!I34 -> 0.073922127 | E24: ='Quality by Seed'!I38 -> 0.072739297 | F24: ='Quality by Seed'!I42 -> 0.51745489 | G24: Below 1.00 = smaller than the seed spread: treat as similar, but keep watching rare classes.
B25: Implementation complexity and limitations | C25: Simplest; no extra dependencies. | D25: Custom attention code; longer-sequence behavior untested. | E25: bitsandbytes dependency; head must stay FP32; CUDA-GPU only. | F25: Needs a trained teacher and a distillation step. | G25: Qualitative; see Methodology for the INT8 head limitation.
A27: Results to treat cautiously (difference from the baseline is smaller than the observed seed spread)
A28: FP32 Linear Attention, Hazmat Recall: mean difference +0.00 pp vs baseline, 0.00 of the larger seed std dev; per-seed paired differences +1.67, +0.00, -1.67 pp.
A29: FP32 Linear Attention, Oversize / Heavy-Haul Recall: mean difference +0.28 pp vs baseline, 0.14 of the larger seed std dev; per-seed paired differences +1.67, -0.83, +0.00 pp.
A30: FP32 Linear Attention, Rare-Class Macro Recall: mean difference +0.14 pp vs baseline, 0.07 of the larger seed std dev; per-seed paired differences +1.67, -0.42, -0.83 pp.
A31: Mixed-Precision INT8 Baseline, Overall Accuracy: mean difference +0.01 pp vs baseline, 0.06 of the larger seed std dev; per-seed paired differences +0.03, +0.03, -0.03 pp.
A32: Mixed-Precision INT8 Baseline, Hazmat Recall: mean difference +0.28 pp vs baseline, 0.13 of the larger seed std dev; per-seed paired differences +0.00, +0.83, +0.00 pp.
A33: Mixed-Precision INT8 Baseline, Oversize / Heavy-Haul Recall: mean difference +0.00 pp vs baseline, 0.00 of the larger seed std dev; per-seed paired differences +0.00, +0.00, +0.00 pp.
A34: Mixed-Precision INT8 Baseline, Rare-Class Macro Recall: mean difference +0.14 pp vs baseline, 0.07 of the larger seed std dev; per-seed paired differences +0.00, +0.42, +0.00 pp.
A35: Distilled Student, Hazmat Recall: mean difference -1.11 pp vs baseline, 0.38 of the larger seed std dev; per-seed paired differences -2.50, +0.00, -0.83 pp.
A36: Distilled Student, Oversize / Heavy-Haul Recall: mean difference -0.83 pp vs baseline, 0.43 of the larger seed std dev; per-seed paired differences +1.67, -2.50, -1.67 pp.
A37: Distilled Student, Rare-Class Macro Recall: mean difference -0.97 pp vs baseline, 0.52 of the larger seed std dev; per-seed paired differences -0.42, -1.25, -1.25 pp.
A39: How strongly to read these results
... A42: All timing comes from one Colab Tesla T4 and one seed-0 model per configuration; Android tablet performance was not measured.
